Workbook

Sheet Tracker
A1: Product Design Task Tracker
A2: PMs add a row per task (columns B–I, including effort estimate in hours). Designers update columns J–M. Everything grey is automatic. Use filters rather than sorting.
B3: ① PM creates the task | J3: ② Designer updates progress | N3: ③ Auto-calculated
A4: Task ID | B4: Task Assigned | C4: Project | D4: PM (Project Lead) | E4: Designer | F4: Priority | G4: Start Date | H4: Target End Date | I4: Estimated Effort (Hrs) | J4: Status | K4: Actual End Date | L4: Revision Rounds | M4: Dependencies / Blockers | N4: TAT (Working Days) | O4: Planned (Working Days) | P4: Variance vs Plan (Days) | Q4: Delivery Status | R4: Speed Score | S4: Quality Score | T4: Task Score | U4: Hours per Working Day
A5: =IF(tblTasks[[#This Row],[Task Assigned]]="","","T-"&TEXT(ROW()-ROW(tblTasks[[#Headers],[Task ID]]),"000")) | D5: =IF(tblTasks[[#This Row],[Project]]="","",IFERROR(INDEX(Settings!$G$5:$G$34,MATCH(tblTasks[[#This Row],[Project]],Settings!$F$5:$F$34,0)),"Not mapped")) | N5: =IF(OR(tblTasks[[#This Row],[Task Assigned]]="",tblTasks[[#This Row],[Start Date]]="",AND(tblTasks[[#This Row],[Actual End Date]]="",tblTasks[[#This Row],[Start Date]]>TODAY())),"",NETWORKDAYS.INTL(tblTasks[[#This Row],[Start Date]],IF(tblTasks[[#This Row],[Actual End Date]]="",TODAY(),tblTasks[[#This Row],[Actual End Date]]),Settings!$J$19,tblHolidays[Holiday Date])) | O5: =IF(OR(tblTasks[[#This Row],[Task Assigned]]="",tblTasks[[#This Row],[Start Date]]="",tblTasks[[#This Row],[Target End Date]]="",tblTasks[[#This Row],[Target End Date]]<tblTasks[[#This Row],[Start Date]]),"",NETWORKDAYS.INTL(tblTasks[[#This Row],[Start Date]],tblTasks[[#This Row],[Target End Date]],Settings!$J$19,tblHolidays[Holiday Date])) | P5: =IF(OR(tblTasks[[#This Row],[Actual End Date]]="",tblTasks[[#This Row],[TAT (Working Days)]]="",tblTasks[[#This Row],[Planned (Working Days)]]=""),"",tblTasks[[#This Row],[TAT (Working Days)]]-tblTasks[[#This Row],[Planned (Working Days)]]) | Q5: =IF(tblTasks[[#This Row],[Task Assigned]]="","",IF(tblTasks[[#This Row],[Start Date]]="","Not Scheduled",IF(tblTasks[[#This Row],[Actual End Date]]<>"",IF(OR(tblTasks[[#This Row],[Target End Date]]="",tblTasks[[#This Row],[Actual End Date]]<=tblTasks[[#This Row],[Target End Date]]),"Done On Time","Done Late"),IF(tblTasks[[#This Row],[Status]]="Blocked","Blocked",IF(AND(tblTasks[[#This Row],[Target End Date]]<>"",TODAY()>tblTasks[[#This Row],[Target End Date]]),"Overdue",IF(tblTasks[[#This Row],[Start Date]]>TODAY(),"Scheduled","On Track")))))) | R5: =IF(OR(tblTasks[[#This Row],[Actual End Date]]="",tblTasks[[#This Row],[TAT (Working Days)]]="",tblTasks[[#This Row],[Planned (Working Days)]]=""),"",100*MIN(1,tblTasks[[#This Row],[Planned (Working Days)]]/MAX(tblTasks[[#This Row],[TAT (Working Days)]],1))) | S5: =IF(tblTasks[[#This Row],[Actual End Date]]="","",100*MAX(0,1-N(tblTasks[[#This Row],[Revision Rounds]])/Settings!$J$9)) | T5: =IF(OR(tblTasks[[#This Row],[Speed Score]]="",tblTasks[[#This Row],[Quality Score]]=""),"",(Settings!$J$5*tblTasks[[#This Row],[Speed Score]]+Settings!$J$6*tblTasks[[#This Row],[Quality Score]])/(Settings!$J$5+Settings!$J$6)) | U5: =IF(OR(tblTasks[[#This Row],[Estimated Effort (Hrs)]]="",tblTasks[[#This Row],[Planned (Working Days)]]=""),"",IF(tblTasks[[#This Row],[Planned (Working Days)]]=0,"",tblTasks[[#This Row],[Estimated Effort (Hrs)]]/tblTasks[[#This Row],[Planned (Working Days)]]))
A6: =IF(tblTasks[[#This Row],[Task Assigned]]="","","T-"&TEXT(ROW()-ROW(tblTasks[[#Headers],[Task ID]]),"000")) | D6: =IF(tblTasks[[#This Row],[Project]]="","",IFERROR(INDEX(Settings!$G$5:$G$34,MATCH(tblTasks[[#This Row],[Project]],Settings!$F$5:$F$34,0)),"Not mapped")) | N6: =IF(OR(tblTasks[[#This Row],[Task Assigned]]="",tblTasks[[#This Row],[Start Date]]="",AND(tblTasks[[#This Row],[Actual End Date]]="",tblTasks[[#This Row],[Start Date]]>TODAY())),"",NETWORKDAYS.INTL(tblTasks[[#This Row],[Start Date]],IF(tblTasks[[#This Row],[Actual End Date]]="",TODAY(),tblTasks[[#This Row],[Actual End Date]]),Settings!$J$19,tblHolidays[Holiday Date])) | O6: =IF(OR(tblTasks[[#This Row],[Task Assigned]]="",tblTasks[[#This Row],[Start Date]]="",tblTasks[[#This Row],[Target End Date]]="",tblTasks[[#This Row],[Target End Date]]<tblTasks[[#This Row],[Start Date]]),"",NETWORKDAYS.INTL(tblTasks[[#This Row],[Start Date]],tblTasks[[#This Row],[Target End Date]],Settings!$J$19,tblHolidays[Holiday Date])) | P6: =IF(OR(tblTasks[[#This Row],[Actual End Date]]="",tblTasks[[#This Row],[TAT (Working Days)]]="",tblTasks[[#This Row],[Planned (Working Days)]]=""),"",tblTasks[[#This Row],[TAT (Working Days)]]-tblTasks[[#This Row],[Planned (Working Days)]]) | Q6: =IF(tblTasks[[#This Row],[Task Assigned]]="","",IF(tblTasks[[#This Row],[Start Date]]="","Not Scheduled",IF(tblTasks[[#This Row],[Actual End Date]]<>"",IF(OR(tblTasks[[#This Row],[Target End Date]]="",tblTasks[[#This Row],[Actual End Date]]<=tblTasks[[#This Row],[Target End Date]]),"Done On Time","Done Late"),IF(tblTasks[[#This Row],[Status]]="Blocked","Blocked",IF(AND(tblTasks[[#This Row],[Target End Date]]<>"",TODAY()>tblTasks[[#This Row],[Target End Date]]),"Overdue",IF(tblTasks[[#This Row],[Start Date]]>TODAY(),"Scheduled","On Track")))))) | R6: =IF(OR(tblTasks[[#This Row],[Actual End Date]]="",tblTasks[[#This Row],[TAT (Working Days)]]="",tblTasks[[#This Row],[Planned (Working Days)]]=""),"",100*MIN(1,tblTasks[[#This Row],[Planned (Working Days)]]/MAX(tblTasks[[#This Row],[TAT (Working Days)]],1))) | S6: =IF(tblTasks[[#This Row],[Actual End Date]]="","",100*MAX(0,1-N(tblTasks[[#This Row],[Revision Rounds]])/Settings!$J$9)) | T6: =IF(OR(tblTasks[[#This Row],[Speed Score]]="",tblTasks[[#This Row],[Quality Score]]=""),"",(Settings!$J$5*tblTasks[[#This Row],[Speed Score]]+Settings!$J$6*tblTasks[[#This Row],[Quality Score]])/(Settings!$J$5+Settings!$J$6)) | U6: =IF(OR(tblTasks[[#This Row],[Estimated Effort (Hrs)]]="",tblTasks[[#This Row],[Planned (Working Days)]]=""),"",IF(tblTasks[[#This Row],[Planned (Working Days)]]=0,"",tblTasks[[#This Row],[Estimated Effort (Hrs)]]/tblTasks[[#This Row],[Planned (Working Days)]]))
A7: =IF(tblTasks[[#This Row],[Task Assigned]]="","","T-"&TEXT(ROW()-ROW(tblTasks[[#Headers],[Task ID]]),"000")) | D7: =IF(tblTasks[[#This Row],[Project]]="","",IFERROR(INDEX(Settings!$G$5:$G$34,MATCH(tblTasks[[#This Row],[Project]],Settings!$F$5:$F$34,0)),"Not mapped")) | N7: =IF(OR(tblTasks[[#This Row],[Task Assigned]]="",tblTasks[[#This Row],[Start Date]]="",AND(tblTasks[[#This Row],[Actual End Date]]="",tblTasks[[#This Row],[Start Date]]>TODAY())),"",NETWORKDAYS.INTL(tblTasks[[#This Row],[Start Date]],IF(tblTasks[[#This Row],[Actual End Date]]="",TODAY(),tblTasks[[#This Row],[Actual End Date]]),Settings!$J$19,tblHolidays[Holiday Date])) | O7: =IF(OR(tblTasks[[#This Row],[Task Assigned]]="",tblTasks[[#This Row],[Start Date]]="",tblTasks[[#This Row],[Target End Date]]="",tblTasks[[#This Row],[Target End Date]]<tblTasks[[#This Row],[Start Date]]),"",NETWORKDAYS.INTL(tblTasks[[#This Row],[Start Date]],tblTasks[[#This Row],[Target End Date]],Settings!$J$19,tblHolidays[Holiday Date])) | P7: =IF(OR(tblTasks[[#This Row],[Actual End Date]]="",tblTasks[[#This Row],[TAT (Working Days)]]="",tblTasks[[#This Row],[Planned (Working Days)]]=""),"",tblTasks[[#This Row],[TAT (Working Days)]]-tblTasks[[#This Row],[Planned (Working Days)]]) | Q7: =IF(tblTasks[[#This Row],[Task Assigned]]="","",IF(tblTasks[[#This Row],[Start Date]]="","Not Scheduled",IF(tblTasks[[#This Row],[Actual End Date]]<>"",IF(OR(tblTasks[[#This Row],[Target End Date]]="",tblTasks[[#This Row],[Actual End Date]]<=tblTasks[[#This Row],[Target End Date]]),"Done On Time","Done Late"),IF(tblTasks[[#This Row],[Status]]="Blocked","Blocked",IF(AND(tblTasks[[#This Row],[Target End Date]]<>"",TODAY()>tblTasks[[#This Row],[Target End Date]]),"Overdue",IF(tblTasks[[#This Row],[Start Date]]>TODAY(),"Scheduled","On Track")))))) | R7: =IF(OR(tblTasks[[#This Row],[Actual End Date]]="",tblTasks[[#This Row],[TAT (Working Days)]]="",tblTasks[[#This Row],[Planned (Working Days)]]=""),"",100*MIN(1,tblTasks[[#This Row],[Planned (Working Days)]]/MAX(tblTasks[[#This Row],[TAT (Working Days)]],1))) | S7: =IF(tblTasks[[#This Row],[Actual End Date]]="","",100*MAX(0,1-N(tblTasks[[#This Row],[Revision Rounds]])/Settings!$J$9)) | T7: =IF(OR(tblTasks[[#This Row],[Speed Score]]="",tblTasks[[#This Row],[Quality Score]]=""),"",(Settings!$J$5*tblTasks[[#This Row],[Speed Score]]+Settings!$J$6*tblTasks[[#This Row],[Quality Score]])/(Settings!$J$5+Settings!$J$6)) | U7: =IF(OR(tblTasks[[#This Row],[Estimated Effort (Hrs)]]="",tblTasks[[#This Row],[Planned (Working Days)]]=""),"",IF(tblTasks[[#This Row],[Planned (Working Days)]]=0,"",tblTasks[[#This Row],[Estimated Effort (Hrs)]]/tblTasks[[#This Row],[Planned (Working Days)]]))
A8: =IF(tblTasks[[#This Row],[Task Assigned]]="","","T-"&TEXT(ROW()-ROW(tblTasks[[#Headers],[Task ID]]),"000")) | D8: =IF(tblTasks[[#This Row],[Project]]="","",IFERROR(INDEX(Settings!$G$5:$G$34,MATCH(tblTasks[[#This Row],[Project]],Settings!$F$5:$F$34,0)),"Not mapped")) | N8: =IF(OR(tblTasks[[#This Row],[Task Assigned]]="",tblTasks[[#This Row],[Start Date]]="",AND(tblTasks[[#This Row],[Actual End Date]]="",tblTasks[[#This Row],[Start Date]]>TODAY())),"",NETWORKDAYS.INTL(tblTasks[[#This Row],[Start Date]],IF(tblTasks[[#This Row],[Actual End Date]]="",TODAY(),tblTasks[[#This Row],[Actual End Date]]),Settings!$J$19,tblHolidays[Holiday Date])) | O8: =IF(OR(tblTasks[[#This Row],[Task Assigned]]="",tblTasks[[#This Row],[Start Date]]="",tblTasks[[#This Row],[Target End Date]]="",tblTasks[[#This Row],[Target End Date]]<tblTasks[[#This Row],[Start Date]]),"",NETWORKDAYS.INTL(tblTasks[[#This Row],[Start Date]],tblTasks[[#This Row],[Target End Date]],Settings!$J$19,tblHolidays[Holiday Date])) | P8: =IF(OR(tblTasks[[#This Row],[Actual End Date]]="",tblTasks[[#This Row],[TAT (Working Days)]]="",tblTasks[[#This Row],[Planned (Working Days)]]=""),"",tblTasks[[#This Row],[TAT (Working Days)]]-tblTasks[[#This Row],[Planned (Working Days)]]) | Q8: =IF(tblTasks[[#This Row],[Task Assigned]]="","",IF(tblTasks[[#This Row],[Start Date]]="","Not Scheduled",IF(tblTasks[[#This Row],[Actual End Date]]<>"",IF(OR(tblTasks[[#This Row],[Target End Date]]="",tblTasks[[#This Row],[Actual End Date]]<=tblTasks[[#This Row],[Target End Date]]),"Done On Time","Done Late"),IF(tblTasks[[#This Row],[Status]]="Blocked","Blocked",IF(AND(tblTasks[[#This Row],[Target End Date]]<>"",TODAY()>tblTasks[[#This Row],[Target End Date]]),"Overdue",IF(tblTasks[[#This Row],[Start Date]]>TODAY(),"Scheduled","On Track")))))) | R8: =IF(OR(tblTasks[[#This Row],[Actual End Date]]="",tblTasks[[#This Row],[TAT (Working Days)]]="",tblTasks[[#This Row],[Planned (Working Days)]]=""),"",100*MIN(1,tblTasks[[#This Row],[Planned (Working Days)]]/MAX(tblTasks[[#This Row],[TAT (Working Days)]],1))) | S8: =IF(tblTasks[[#This Row],[Actual End Date]]="","",100*MAX(0,1-N(tblTasks[[#This Row],[Revision Rounds]])/Settings!$J$9)) | T8: =IF(OR(tblTasks[[#This Row],[Speed Score]]="",tblTasks[[#This Row],[Quality Score]]=""),"",(Settings!$J$5*tblTasks[[#This Row],[Speed Score]]+Settings!$J$6*tblTasks[[#This Row],[Quality Score]])/(Settings!$J$5+Settings!$J$6)) | U8: =IF(OR(tblTasks[[#This Row],[Estimated Effort (Hrs)]]="",tblTasks[[#This Row],[Planned (Working Days)]]=""),"",IF(tblTasks[[#This Row],[Planned (Working Days)]]=0,"",tblTasks[[#This Row],[Estimated Effort (Hrs)]]/tblTasks[[#This Row],[Planned (Working Days)]]))
A9: =IF(tblTasks[[#This Row],[Task Assigned]]="","","T-"&TEXT(ROW()-ROW(tblTasks[[#Headers],[Task ID]]),"000")) | D9: =IF(tblTasks[[#This Row],[Project]]="","",IFERROR(INDEX(Settings!$G$5:$G$34,MATCH(tblTasks[[#This Row],[Project]],Settings!$F$5:$F$34,0)),"Not mapped")) | N9: =IF(OR(tblTasks[[#This Row],[Task Assigned]]="",tblTasks[[#This Row],[Start Date]]="",AND(tblTasks[[#This Row],[Actual End Date]]="",tblTasks[[#This Row],[Start Date]]>TODAY())),"",NETWORKDAYS.INTL(tblTasks[[#This Row],[Start Date]],IF(tblTasks[[#This Row],[Actual End Date]]="",TODAY(),tblTasks[[#This Row],[Actual End Date]]),Settings!$J$19,tblHolidays[Holiday Date])) | O9: =IF(OR(tblTasks[[#This Row],[Task Assigned]]="",tblTasks[[#This Row],[Start Date]]="",tblTasks[[#This Row],[Target End Date]]="",tblTasks[[#This Row],[Target End Date]]<tblTasks[[#This Row],[Start Date]]),"",NETWORKDAYS.INTL(tblTasks[[#This Row],[Start Date]],tblTasks[[#This Row],[Target End Date]],Settings!$J$19,tblHolidays[Holiday Date])) | P9: =IF(OR(tblTasks[[#This Row],[Actual End Date]]="",tblTasks[[#This Row],[TAT (Working Days)]]="",tblTasks[[#This Row],[Planned (Working Days)]]=""),"",tblTasks[[#This Row],[TAT (Working Days)]]-tblTasks[[#This Row],[Planned (Working Days)]]) | Q9: =IF(tblTasks[[#This Row],[Task Assigned]]="","",IF(tblTasks[[#This Row],[Start Date]]="","Not Scheduled",IF(tblTasks[[#This Row],[Actual End Date]]<>"",IF(OR(tblTasks[[#This Row],[Target End Date]]="",tblTasks[[#This Row],[Actual End Date]]<=tblTasks[[#This Row],[Target End Date]]),"Done On Time","Done Late"),IF(tblTasks[[#This Row],[Status]]="Blocked","Blocked",IF(AND(tblTasks[[#This Row],[Target End Date]]<>"",TODAY()>tblTasks[[#This Row],[Target End Date]]),"Overdue",IF(tblTasks[[#This Row],[Start Date]]>TODAY(),"Scheduled","On Track")))))) | R9: =IF(OR(tblTasks[[#This Row],[Actual End Date]]="",tblTasks[[#This Row],[TAT (Working Days)]]="",tblTasks[[#This Row],[Planned (Working Days)]]=""),"",100*MIN(1,tblTasks[[#This Row],[Planned (Working Days)]]/MAX(tblTasks[[#This Row],[TAT (Working Days)]],1))) | S9: =IF(tblTasks[[#This Row],[Actual End Date]]="","",100*MAX(0,1-N(tblTasks[[#This Row],[Revision Rounds]])/Settings!$J$9)) | T9: =IF(OR(tblTasks[[#This Row],[Speed Score]]="",tblTasks[[#This Row],[Quality Score]]=""),"",(Settings!$J$5*tblTasks[[#This Row],[Speed Score]]+Settings!$J$6*tblTasks[[#This Row],[Quality Score]])/(Settings!$J$5+Settings!$J$6)) | U9: =IF(OR(tblTasks[[#This Row],[Estimated Effort (Hrs)]]="",tblTasks[[#This Row],[Planned (Working Days)]]=""),"",IF(tblTasks[[#This Row],[Planned (Working Days)]]=0,"",tblTasks[[#This Row],[Estimated Effort (Hrs)]]/tblTasks[[#This Row],[Planned (Working Days)]]))
A10: =IF(tblTasks[[#This Row],[Task Assigned]]="","","T-"&TEXT(ROW()-ROW(tblTasks[[#Headers],[Task ID]]),"000")) | D10: =IF(tblTasks[[#This Row],[Project]]="","",IFERROR(INDEX(Settings!$G$5:$G$34,MATCH(tblTasks[[#This Row],[Project]],Settings!$F$5:$F$34,0)),"Not mapped")) | N10: =IF(OR(tblTasks[[#This Row],[Task Assigned]]="",tblTasks[[#This Row],[Start Date]]="",AND(tblTasks[[#This Row],[Actual End Date]]="",tblTasks[[#This Row],[Start Date]]>TODAY())),"",NETWORKDAYS.INTL(tblTasks[[#This Row],[Start Date]],IF(tblTasks[[#This Row],[Actual End Date]]="",TODAY(),tblTasks[[#This Row],[Actual End Date]]),Settings!$J$19,tblHolidays[Holiday Date])) | O10: =IF(OR(tblTasks[[#This Row],[Task Assigned]]="",tblTasks[[#This Row],[Start Date]]="",tblTasks[[#This Row],[Target End Date]]="",tblTasks[[#This Row],[Target End Date]]<tblTasks[[#This Row],[Start Date]]),"",NETWORKDAYS.INTL(tblTasks[[#This Row],[Start Date]],tblTasks[[#This Row],[Target End Date]],Settings!$J$19,tblHolidays[Holiday Date])) | P10: =IF(OR(tblTasks[[#This Row],[Actual End Date]]="",tblTasks[[#This Row],[TAT (Working Days)]]="",tblTasks[[#This Row],[Planned (Working Days)]]=""),"",tblTasks[[#This Row],[TAT (Working Days)]]-tblTasks[[#This Row],[Planned (Working Days)]]) | Q10: =IF(tblTasks[[#This Row],[Task Assigned]]="","",IF(tblTasks[[#This Row],[Start Date]]="","Not Scheduled",IF(tblTasks[[#This Row],[Actual End Date]]<>"",IF(OR(tblTasks[[#This Row],[Target End Date]]="",tblTasks[[#This Row],[Actual End Date]]<=tblTasks[[#This Row],[Target End Date]]),"Done On Time","Done Late"),IF(tblTasks[[#This Row],[Status]]="Blocked","Blocked",IF(AND(tblTasks[[#This Row],[Target End Date]]<>"",TODAY()>tblTasks[[#This Row],[Target End Date]]),"Overdue",IF(tblTasks[[#This Row],[Start Date]]>TODAY(),"Scheduled","On Track")))))) | R10: =IF(OR(tblTasks[[#This Row],[Actual End Date]]="",tblTasks[[#This Row],[TAT (Working Days)]]="",tblTasks[[#This Row],[Planned (Working Days)]]=""),"",100*MIN(1,tblTasks[[#This Row],[Planned (Working Days)]]/MAX(tblTasks[[#This Row],[TAT (Working Days)]],1))) | S10: =IF(tblTasks[[#This Row],[Actual End Date]]="","",100*MAX(0,1-N(tblTasks[[#This Row],[Revision Rounds]])/Settings!$J$9)) | T10: =IF(OR(tblTasks[[#This Row],[Speed Score]]="",tblTasks[[#This Row],[Quality Score]]=""),"",(Settings!$J$5*tblTasks[[#This Row],[Speed Score]]+Settings!$J$6*tblTasks[[#This Row],[Quality Score]])/(Settings!$J$5+Settings!$J$6)) | U10: =IF(OR(tblTasks[[#This Row],[Estimated Effort (Hrs)]]="",tblTasks[[#This Row],[Planned (Working Days)]]=""),"",IF(tblTasks[[#This Row],[Planned (Working Days)]]=0,"",tblTasks[[#This Row],[Estimated Effort (Hrs)]]/tblTasks[[#This Row],[Planned (Working Days)]]))
A11: =IF(tblTasks[[#This Row],[Task Assigned]]="","","T-"&TEXT(ROW()-ROW(tblTasks[[#Headers],[Task ID]]),"000")) | D11: =IF(tblTasks[[#This Row],[Project]]="","",IFERROR(INDEX(Settings!$G$5:$G$34,MATCH(tblTasks[[#This Row],[Project]],Settings!$F$5:$F$34,0)),"Not mapped")) | N11: =IF(OR(tblTasks[[#This Row],[Task Assigned]]="",tblTasks[[#This Row],[Start Date]]="",AND(tblTasks[[#This Row],[Actual End Date]]="",tblTasks[[#This Row],[Start Date]]>TODAY())),"",NETWORKDAYS.INTL(tblTasks[[#This Row],[Start Date]],IF(tblTasks[[#This Row],[Actual End Date]]="",TODAY(),tblTasks[[#This Row],[Actual End Date]]),Settings!$J$19,tblHolidays[Holiday Date])) | O11: =IF(OR(tblTasks[[#This Row],[Task Assigned]]="",tblTasks[[#This Row],[Start Date]]="",tblTasks[[#This Row],[Target End Date]]="",tblTasks[[#This Row],[Target End Date]]<tblTasks[[#This Row],[Start Date]]),"",NETWORKDAYS.INTL(tblTasks[[#This Row],[Start Date]],tblTasks[[#This Row],[Target End Date]],Settings!$J$19,tblHolidays[Holiday Date])) | P11: =IF(OR(tblTasks[[#This Row],[Actual End Date]]="",tblTasks[[#This Row],[TAT (Working Days)]]="",tblTasks[[#This Row],[Planned (Working Days)]]=""),"",tblTasks[[#This Row],[TAT (Working Days)]]-tblTasks[[#This Row],[Planned (Working Days)]]) | Q11: =IF(tblTasks[[#This Row],[Task Assigned]]="","",IF(tblTasks[[#This Row],[Start Date]]="","Not Scheduled",IF(tblTasks[[#This Row],[Actual End Date]]<>"",IF(OR(tblTasks[[#This Row],[Target End Date]]="",tblTasks[[#This Row],[Actual End Date]]<=tblTasks[[#This Row],[Target End Date]]),"Done On Time","Done Late"),IF(tblTasks[[#This Row],[Status]]="Blocked","Blocked",IF(AND(tblTasks[[#This Row],[Target End Date]]<>"",TODAY()>tblTasks[[#This Row],[Target End Date]]),"Overdue",IF(tblTasks[[#This Row],[Start Date]]>TODAY(),"Scheduled","On Track")))))) | R11: =IF(OR(tblTasks[[#This Row],[Actual End Date]]="",tblTasks[[#This Row],[TAT (Working Days)]]="",tblTasks[[#This Row],[Planned (Working Days)]]=""),"",100*MIN(1,tblTasks[[#This Row],[Planned (Working Days)]]/MAX(tblTasks[[#This Row],[TAT (Working Days)]],1))) | S11: =IF(tblTasks[[#This Row],[Actual End Date]]="","",100*MAX(0,1-N(tblTasks[[#This Row],[Revision Rounds]])/Settings!$J$9)) | T11: =IF(OR(tblTasks[[#This Row],[Speed Score]]="",tblTasks[[#This Row],[Quality Score]]=""),"",(Settings!$J$5*tblTasks[[#This Row],[Speed Score]]+Settings!$J$6*tblTasks[[#This Row],[Quality Score]])/(Settings!$J$5+Settings!$J$6)) | U11: =IF(OR(tblTasks[[#This Row],[Estimated Effort (Hrs)]]="",tblTasks[[#This Row],[Planned (Working Days)]]=""),"",IF(tblTasks[[#This Row],[Planned (Working Days)]]=0,"",tblTasks[[#This Row],[Estimated Effort (Hrs)]]/tblTasks[[#This Row],[Planned (Working Days)]]))
A12: =IF(tblTasks[[#This Row],[Task Assigned]]="","","T-"&TEXT(ROW()-ROW(tblTasks[[#Headers],[Task ID]]),"000")) | D12: =IF(tblTasks[[#This Row],[Project]]="","",IFERROR(INDEX(Settings!$G$5:$G$34,MATCH(tblTasks[[#This Row],[Project]],Settings!$F$5:$F$34,0)),"Not mapped")) | N12: =IF(OR(tblTasks[[#This Row],[Task Assigned]]="",tblTasks[[#This Row],[Start Date]]="",AND(tblTasks[[#This Row],[Actual End Date]]="",tblTasks[[#This Row],[Start Date]]>TODAY())),"",NETWORKDAYS.INTL(tblTasks[[#This Row],[Start Date]],IF(tblTasks[[#This Row],[Actual End Date]]="",TODAY(),tblTasks[[#This Row],[Actual End Date]]),Settings!$J$19,tblHolidays[Holiday Date])) | O12: =IF(OR(tblTasks[[#This Row],[Task Assigned]]="",tblTasks[[#This Row],[Start Date]]="",tblTasks[[#This Row],[Target End Date]]="",tblTasks[[#This Row],[Target End Date]]<tblTasks[[#This Row],[Start Date]]),"",NETWORKDAYS.INTL(tblTasks[[#This Row],[Start Date]],tblTasks[[#This Row],[Target End Date]],Settings!$J$19,tblHolidays[Holiday Date])) | P12: =IF(OR(tblTasks[[#This Row],[Actual End Date]]="",tblTasks[[#This Row],[TAT (Working Days)]]="",tblTasks[[#This Row],[Planned (Working Days)]]=""),"",tblTasks[[#This Row],[TAT (Working Days)]]-tblTasks[[#This Row],[Planned (Working Days)]]) | Q12: =IF(tblTasks[[#This Row],[Task Assigned]]="","",IF(tblTasks[[#This Row],[Start Date]]="","Not Scheduled",IF(tblTasks[[#This Row],[Actual End Date]]<>"",IF(OR(tblTasks[[#This Row],[Target End Date]]="",tblTasks[[#This Row],[Actual End Date]]<=tblTasks[[#This Row],[Target End Date]]),"Done On Time","Done Late"),IF(tblTasks[[#This Row],[Status]]="Blocked","Blocked",IF(AND(tblTasks[[#This Row],[Target End Date]]<>"",TODAY()>tblTasks[[#This Row],[Target End Date]]),"Overdue",IF(tblTasks[[#This Row],[Start Date]]>TODAY(),"Scheduled","On Track")))))) | R12: =IF(OR(tblTasks[[#This Row],[Actual End Date]]="",tblTasks[[#This Row],[TAT (Working Days)]]="",tblTasks[[#This Row],[Planned (Working Days)]]=""),"",100*MIN(1,tblTasks[[#This Row],[Planned (Working Days)]]/MAX(tblTasks[[#This Row],[TAT (Working Days)]],1))) | S12: =IF(tblTasks[[#This Row],[Actual End Date]]="","",100*MAX(0,1-N(tblTasks[[#This Row],[Revision Rounds]])/Settings!$J$9)) | T12: =IF(OR(tblTasks[[#This Row],[Speed Score]]="",tblTasks[[#This Row],[Quality Score]]=""),"",(Settings!$J$5*tblTasks[[#This Row],[Speed Score]]+Settings!$J$6*tblTasks[[#This Row],[Quality Score]])/(Settings!$J$5+Settings!$J$6)) | U12: =IF(OR(tblTasks[[#This Row],[Estimated Effort (Hrs)]]="",tblTasks[[#This Row],[Planned (Working Days)]]=""),"",IF(tblTasks[[#This Row],[Planned (Working Days)]]=0,"",tblTasks[[#This Row],[Estimated Effort (Hrs)]]/tblTasks[[#This Row],[Planned (Working Days)]]))
A13: =IF(tblTasks[[#This Row],[Task Assigned]]="","","T-"&TEXT(ROW()-ROW(tblTasks[[#Headers],[Task ID]]),"000")) | D13: =IF(tblTasks[[#This Row],[Project]]="","",IFERROR(INDEX(Settings!$G$5:$G$34,MATCH(tblTasks[[#This Row],[Project]],Settings!$F$5:$F$34,0)),"Not mapped")) | N13: =IF(OR(tblTasks[[#This Row],[Task Assigned]]="",tblTasks[[#This Row],[Start Date]]="",AND(tblTasks[[#This Row],[Actual End Date]]="",tblTasks[[#This Row],[Start Date]]>TODAY())),"",NETWORKDAYS.INTL(tblTasks[[#This Row],[Start Date]],IF(tblTasks[[#This Row],[Actual End Date]]="",TODAY(),tblTasks[[#This Row],[Actual End Date]]),Settings!$J$19,tblHolidays[Holiday Date])) | O13: =IF(OR(tblTasks[[#This Row],[Task Assigned]]="",tblTasks[[#This Row],[Start Date]]="",tblTasks[[#This Row],[Target End Date]]="",tblTasks[[#This Row],[Target End Date]]<tblTasks[[#This Row],[Start Date]]),"",NETWORKDAYS.INTL(tblTasks[[#This Row],[Start Date]],tblTasks[[#This Row],[Target End Date]],Settings!$J$19,tblHolidays[Holiday Date])) | P13: =IF(OR(tblTasks[[#This Row],[Actual End Date]]="",tblTasks[[#This Row],[TAT (Working Days)]]="",tblTasks[[#This Row],[Planned (Working Days)]]=""),"",tblTasks[[#This Row],[TAT (Working Days)]]-tblTasks[[#This Row],[Planned (Working Days)]]) | Q13: =IF(tblTasks[[#This Row],[Task Assigned]]="","",IF(tblTasks[[#This Row],[Start Date]]="","Not Scheduled",IF(tblTasks[[#This Row],[Actual End Date]]<>"",IF(OR(tblTasks[[#This Row],[Target End Date]]="",tblTasks[[#This Row],[Actual End Date]]<=tblTasks[[#This Row],[Target End Date]]),"Done On Time","Done Late"),IF(tblTasks[[#This Row],[Status]]="Blocked","Blocked",IF(AND(tblTasks[[#This Row],[Target End Date]]<>"",TODAY()>tblTasks[[#This Row],[Target End Date]]),"Overdue",IF(tblTasks[[#This Row],[Start Date]]>TODAY(),"Scheduled","On Track")))))) | R13: =IF(OR(tblTasks[[#This Row],[Actual End Date]]="",tblTasks[[#This Row],[TAT (Working Days)]]="",tblTasks[[#This Row],[Planned (Working Days)]]=""),"",100*MIN(1,tblTasks[[#This Row],[Planned (Working Days)]]/MAX(tblTasks[[#This Row],[TAT (Working Days)]],1))) | S13: =IF(tblTasks[[#This Row],[Actual End Date]]="","",100*MAX(0,1-N(tblTasks[[#This Row],[Revision Rounds]])/Settings!$J$9)) | T13: =IF(OR(tblTasks[[#This Row],[Speed Score]]="",tblTasks[[#This Row],[Quality Score]]=""),"",(Settings!$J$5*tblTasks[[#This Row],[Speed Score]]+Settings!$J$6*tblTasks[[#This Row],[Quality Score]])/(Settings!$J$5+Settings!$J$6)) | U13: =IF(OR(tblTasks[[#This Row],[Estimated Effort (Hrs)]]="",tblTasks[[#This Row],[Planned (Working Days)]]=""),"",IF(tblTasks[[#This Row],[Planned (Working Days)]]=0,"",tblTasks[[#This Row],[Estimated Effort (Hrs)]]/tblTasks[[#This Row],[Planned (Working Days)]]))
A14: =IF(tblTasks[[#This Row],[Task Assigned]]="","","T-"&TEXT(ROW()-ROW(tblTasks[[#Headers],[Task ID]]),"000")) | D14: =IF(tblTasks[[#This Row],[Project]]="","",IFERROR(INDEX(Settings!$G$5:$G$34,MATCH(tblTasks[[#This Row],[Project]],Settings!$F$5:$F$34,0)),"Not mapped")) | N14: =IF(OR(tblTasks[[#This Row],[Task Assigned]]="",tblTasks[[#This Row],[Start Date]]="",AND(tblTasks[[#This Row],[Actual End Date]]="",tblTasks[[#This Row],[Start Date]]>TODAY())),"",NETWORKDAYS.INTL(tblTasks[[#This Row],[Start Date]],IF(tblTasks[[#This Row],[Actual End Date]]="",TODAY(),tblTasks[[#This Row],[Actual End Date]]),Settings!$J$19,tblHolidays[Holiday Date])) | O14: =IF(OR(tblTasks[[#This Row],[Task Assigned]]="",tblTasks[[#This Row],[Start Date]]="",tblTasks[[#This Row],[Target End Date]]="",tblTasks[[#This Row],[Target End Date]]<tblTasks[[#This Row],[Start Date]]),"",NETWORKDAYS.INTL(tblTasks[[#This Row],[Start Date]],tblTasks[[#This Row],[Target End Date]],Settings!$J$19,tblHolidays[Holiday Date])) | P14: =IF(OR(tblTasks[[#This Row],[Actual End Date]]="",tblTasks[[#This Row],[TAT (Working Days)]]="",tblTasks[[#This Row],[Planned (Working Days)]]=""),"",tblTasks[[#This Row],[TAT (Working Days)]]-tblTasks[[#This Row],[Planned (Working Days)]]) | Q14: =IF(tblTasks[[#This Row],[Task Assigned]]="","",IF(tblTasks[[#This Row],[Start Date]]="","Not Scheduled",IF(tblTasks[[#This Row],[Actual End Date]]<>"",IF(OR(tblTasks[[#This Row],[Target End Date]]="",tblTasks[[#This Row],[Actual End Date]]<=tblTasks[[#This Row],[Target End Date]]),"Done On Time","Done Late"),IF(tblTasks[[#This Row],[Status]]="Blocked","Blocked",IF(AND(tblTasks[[#This Row],[Target End Date]]<>"",TODAY()>tblTasks[[#This Row],[Target End Date]]),"Overdue",IF(tblTasks[[#This Row],[Start Date]]>TODAY(),"Scheduled","On Track")))))) | R14: =IF(OR(tblTasks[[#This Row],[Actual End Date]]="",tblTasks[[#This Row],[TAT (Working Days)]]="",tblTasks[[#This Row],[Planned (Working Days)]]=""),"",100*MIN(1,tblTasks[[#This Row],[Planned (Working Days)]]/MAX(tblTasks[[#This Row],[TAT (Working Days)]],1))) | S14: =IF(tblTasks[[#This Row],[Actual End Date]]="","",100*MAX(0,1-N(tblTasks[[#This Row],[Revision Rounds]])/Settings!$J$9)) | T14: =IF(OR(tblTasks[[#This Row],[Speed Score]]="",tblTasks[[#This Row],[Quality Score]]=""),"",(Settings!$J$5*tblTasks[[#This Row],[Speed Score]]+Settings!$J$6*tblTasks[[#This Row],[Quality Score]])/(Settings!$J$5+Settings!$J$6)) | U14: =IF(OR(tblTasks[[#This Row],[Estimated Effort (Hrs)]]="",tblTasks[[#This Row],[Planned (Working Days)]]=""),"",IF(tblTasks[[#This Row],[Planned (Working Days)]]=0,"",tblTasks[[#This Row],[Estimated Effort (Hrs)]]/tblTasks[[#This Row],[Planned (Working Days)]]))
A15: =IF(tblTasks[[#This Row],[Task Assigned]]="","","T-"&TEXT(ROW()-ROW(tblTasks[[#Headers],[Task ID]]),"000")) | D15: =IF(tblTasks[[#This Row],[Project]]="","",IFERROR(INDEX(Settings!$G$5:$G$34,MATCH(tblTasks[[#This Row],[Project]],Settings!$F$5:$F$34,0)),"Not mapped")) | N15: =IF(OR(tblTasks[[#This Row],[Task Assigned]]="",tblTasks[[#This Row],[Start Date]]="",AND(tblTasks[[#This Row],[Actual End Date]]="",tblTasks[[#This Row],[Start Date]]>TODAY())),"",NETWORKDAYS.INTL(tblTasks[[#This Row],[Start Date]],IF(tblTasks[[#This Row],[Actual End Date]]="",TODAY(),tblTasks[[#This Row],[Actual End Date]]),Settings!$J$19,tblHolidays[Holiday Date])) | O15: =IF(OR(tblTasks[[#This Row],[Task Assigned]]="",tblTasks[[#This Row],[Start Date]]="",tblTasks[[#This Row],[Target End Date]]="",tblTasks[[#This Row],[Target End Date]]<tblTasks[[#This Row],[Start Date]]),"",NETWORKDAYS.INTL(tblTasks[[#This Row],[Start Date]],tblTasks[[#This Row],[Target End Date]],Settings!$J$19,tblHolidays[Holiday Date])) | P15: =IF(OR(tblTasks[[#This Row],[Actual End Date]]="",tblTasks[[#This Row],[TAT (Working Days)]]="",tblTasks[[#This Row],[Planned (Working Days)]]=""),"",tblTasks[[#This Row],[TAT (Working Days)]]-tblTasks[[#This Row],[Planned (Working Days)]]) | Q15: =IF(tblTasks[[#This Row],[Task Assigned]]="","",IF(tblTasks[[#This Row],[Start Date]]="","Not Scheduled",IF(tblTasks[[#This Row],[Actual End Date]]<>"",IF(OR(tblTasks[[#This Row],[Target End Date]]="",tblTasks[[#This Row],[Actual End Date]]<=tblTasks[[#This Row],[Target End Date]]),"Done On Time","Done Late"),IF(tblTasks[[#This Row],[Status]]="Blocked","Blocked",IF(AND(tblTasks[[#This Row],[Target End Date]]<>"",TODAY()>tblTasks[[#This Row],[Target End Date]]),"Overdue",IF(tblTasks[[#This Row],[Start Date]]>TODAY(),"Scheduled","On Track")))))) | R15: =IF(OR(tblTasks[[#This Row],[Actual End Date]]="",tblTasks[[#This Row],[TAT (Working Days)]]="",tblTasks[[#This Row],[Planned (Working Days)]]=""),"",100*MIN(1,tblTasks[[#This Row],[Planned (Working Days)]]/MAX(tblTasks[[#This Row],[TAT (Working Days)]],1))) | S15: =IF(tblTasks[[#This Row],[Actual End Date]]="","",100*MAX(0,1-N(tblTasks[[#This Row],[Revision Rounds]])/Settings!$J$9)) | T15: =IF(OR(tblTasks[[#This Row],[Speed Score]]="",tblTasks[[#This Row],[Quality Score]]=""),"",(Settings!$J$5*tblTasks[[#This Row],[Speed Score]]+Settings!$J$6*tblTasks[[#This Row],[Quality Score]])/(Settings!$J$5+Settings!$J$6)) | U15: =IF(OR(tblTasks[[#This Row],[Estimated Effort (Hrs)]]="",tblTasks[[#This Row],[Planned (Working Days)]]=""),"",IF(tblTasks[[#This Row],[Planned (Working Days)]]=0,"",tblTasks[[#This Row],[Estimated Effort (Hrs)]]/tblTasks[[#This Row],[Planned (Working Days)]]))
A16: =IF(tblTasks[[#This Row],[Task Assigned]]="","","T-"&TEXT(ROW()-ROW(tblTasks[[#Headers],[Task ID]]),"000")) | D16: =IF(tblTasks[[#This Row],[Project]]="","",IFERROR(INDEX(Settings!$G$5:$G$34,MATCH(tblTasks[[#This Row],[Project]],Settings!$F$5:$F$34,0)),"Not mapped")) | N16: =IF(OR(tblTasks[[#This Row],[Task Assigned]]="",tblTasks[[#This Row],[Start Date]]="",AND(tblTasks[[#This Row],[Actual End Date]]="",tblTasks[[#This Row],[Start Date]]>TODAY())),"",NETWORKDAYS.INTL(tblTasks[[#This Row],[Start Date]],IF(tblTasks[[#This Row],[Actual End Date]]="",TODAY(),tblTasks[[#This Row],[Actual End Date]]),Settings!$J$19,tblHolidays[Holiday Date])) | O16: =IF(OR(tblTasks[[#This Row],[Task Assigned]]="",tblTasks[[#This Row],[Start Date]]="",tblTasks[[#This Row],[Target End Date]]="",tblTasks[[#This Row],[Target End Date]]<tblTasks[[#This Row],[Start Date]]),"",NETWORKDAYS.INTL(tblTasks[[#This Row],[Start Date]],tblTasks[[#This Row],[Target End Date]],Settings!$J$19,tblHolidays[Holiday Date])) | P16: =IF(OR(tblTasks[[#This Row],[Actual End Date]]="",tblTasks[[#This Row],[TAT (Working Days)]]="",tblTasks[[#This Row],[Planned (Working Days)]]=""),"",tblTasks[[#This Row],[TAT (Working Days)]]-tblTasks[[#This Row],[Planned (Working Days)]]) | Q16: =IF(tblTasks[[#This Row],[Task Assigned]]="","",IF(tblTasks[[#This Row],[Start Date]]="","Not Scheduled",IF(tblTasks[[#This Row],[Actual End Date]]<>"",IF(OR(tblTasks[[#This Row],[Target End Date]]="",tblTasks[[#This Row],[Actual End Date]]<=tblTasks[[#This Row],[Target End Date]]),"Done On Time","Done Late"),IF(tblTasks[[#This Row],[Status]]="Blocked","Blocked",IF(AND(tblTasks[[#This Row],[Target End Date]]<>"",TODAY()>tblTasks[[#This Row],[Target End Date]]),"Overdue",IF(tblTasks[[#This Row],[Start Date]]>TODAY(),"Scheduled","On Track")))))) | R16: =IF(OR(tblTasks[[#This Row],[Actual End Date]]="",tblTasks[[#This Row],[TAT (Working Days)]]="",tblTasks[[#This Row],[Planned (Working Days)]]=""),"",100*MIN(1,tblTasks[[#This Row],[Planned (Working Days)]]/MAX(tblTasks[[#This Row],[TAT (Working Days)]],1))) | S16: =IF(tblTasks[[#This Row],[Actual End Date]]="","",100*MAX(0,1-N(tblTasks[[#This Row],[Revision Rounds]])/Settings!$J$9)) | T16: =IF(OR(tblTasks[[#This Row],[Speed Score]]="",tblTasks[[#This Row],[Quality Score]]=""),"",(Settings!$J$5*tblTasks[[#This Row],[Speed Score]]+Settings!$J$6*tblTasks[[#This Row],[Quality Score]])/(Settings!$J$5+Settings!$J$6)) | U16: =IF(OR(tblTasks[[#This Row],[Estimated Effort (Hrs)]]="",tblTasks[[#This Row],[Planned (Working Days)]]=""),"",IF(tblTasks[[#This Row],[Planned (Working Days)]]=0,"",tblTasks[[#This Row],[Estimated Effort (Hrs)]]/tblTasks[[#This Row],[Planned (Working Days)]]))
... A54: =IF(tblTasks[[#This Row],[Task Assigned]]="","","T-"&TEXT(ROW()-ROW(tblTasks[[#Headers],[Task ID]]),"000")) | D54: =IF(tblTasks[[#This Row],[Project]]="","",IFERROR(INDEX(Settings!$G$5:$G$34,MATCH(tblTasks[[#This Row],[Project]],Settings!$F$5:$F$34,0)),"Not mapped")) | N54: =IF(OR(tblTasks[[#This Row],[Task Assigned]]="",tblTasks[[#This Row],[Start Date]]="",AND(tblTasks[[#This Row],[Actual End Date]]="",tblTasks[[#This Row],[Start Date]]>TODAY())),"",NETWORKDAYS.INTL(tblTasks[[#This Row],[Start Date]],IF(tblTasks[[#This Row],[Actual End Date]]="",TODAY(),tblTasks[[#This Row],[Actual End Date]]),Settings!$J$19,tblHolidays[Holiday Date])) | O54: =IF(OR(tblTasks[[#This Row],[Task Assigned]]="",tblTasks[[#This Row],[Start Date]]="",tblTasks[[#This Row],[Target End Date]]="",tblTasks[[#This Row],[Target End Date]]<tblTasks[[#This Row],[Start Date]]),"",NETWORKDAYS.INTL(tblTasks[[#This Row],[Start Date]],tblTasks[[#This Row],[Target End Date]],Settings!$J$19,tblHolidays[Holiday Date])) | P54: =IF(OR(tblTasks[[#This Row],[Actual End Date]]="",tblTasks[[#This Row],[TAT (Working Days)]]="",tblTasks[[#This Row],[Planned (Working Days)]]=""),"",tblTasks[[#This Row],[TAT (Working Days)]]-tblTasks[[#This Row],[Planned (Working Days)]]) | Q54: =IF(tblTasks[[#This Row],[Task Assigned]]="","",IF(tblTasks[[#This Row],[Start Date]]="","Not Scheduled",IF(tblTasks[[#This Row],[Actual End Date]]<>"",IF(OR(tblTasks[[#This Row],[Target End Date]]="",tblTasks[[#This Row],[Actual End Date]]<=tblTasks[[#This Row],[Target End Date]]),"Done On Time","Done Late"),IF(tblTasks[[#This Row],[Status]]="Blocked","Blocked",IF(AND(tblTasks[[#This Row],[Target End Date]]<>"",TODAY()>tblTasks[[#This Row],[Target End Date]]),"Overdue",IF(tblTasks[[#This Row],[Start Date]]>TODAY(),"Scheduled","On Track")))))) | R54: =IF(OR(tblTasks[[#This Row],[Actual End Date]]="",tblTasks[[#This Row],[TAT (Working Days)]]="",tblTasks[[#This Row],[Planned (Working Days)]]=""),"",100*MIN(1,tblTasks[[#This Row],[Planned (Working Days)]]/MAX(tblTasks[[#This Row],[TAT (Working Days)]],1))) | S54: =IF(tblTasks[[#This Row],[Actual End Date]]="","",100*MAX(0,1-N(tblTasks[[#This Row],[Revision Rounds]])/Settings!$J$9)) | T54: =IF(OR(tblTasks[[#This Row],[Speed Score]]="",tblTasks[[#This Row],[Quality Score]]=""),"",(Settings!$J$5*tblTasks[[#This Row],[Speed Score]]+Settings!$J$6*tblTasks[[#This Row],[Quality Score]])/(Settings!$J$5+Settings!$J$6)) | U54: =IF(OR(tblTasks[[#This Row],[Estimated Effort (Hrs)]]="",tblTasks[[#This Row],[Planned (Working Days)]]=""),"",IF(tblTasks[[#This Row],[Planned (Working Days)]]=0,"",tblTasks[[#This Row],[Estimated Effort (Hrs)]]/tblTasks[[#This Row],[Planned (Working Days)]]))

Sheet Scorecard
A1: Designer Scorecard
A2: Live from the Tracker. Scores are 0–100. Speed and Quality use tasks completed in the period below; Commitment is as of today.
A4: Period from | B4: 46266
A5: Period to | B5: 46295
A7: Total Tasks | B7: Completed | C7: Open | D7: Blocked | E7: Overdue
A8: =COUNTA(tblTasks[Task Assigned]) -> 0 | B8: =COUNTIFS(tblTasks[Delivery Status],"Done*") -> 0 | C8: =A8-B8 -> 0 | D8: =COUNTIFS(tblTasks[Delivery Status],"Blocked") -> 0 | E8: =COUNTIFS(tblTasks[Delivery Status],"Overdue") -> 0
A10: Score by designer
A11: Designer | B11: Tasks Completed (period) | C11: Avg TAT (Working Days) | D11: On-Time % | E11: Avg Revision Rounds | F11: Speed Score | G11: Quality Score | H11: Commitment Score | I11: Overall Score | J11: Rating | K11: Focus Area
A12: =IF(Settings!A5="","",Settings!A5) -> Pragati | B12: =IF($A12="","",COUNTIFS(tblTasks[Designer],$A12,tblTasks[Actual End Date],">="&$B$4,tblTasks[Actual End Date],"<="&$B$5)) -> 0 | C12: =IF($A12="","",IF(B12=0,"-",IFERROR(AVERAGEIFS(tblTasks[TAT (Working Days)],tblTasks[Designer],$A12,tblTasks[Actual End Date],">="&$B$4,tblTasks[Actual End Date],"<="&$B$5),"-"))) -> - | D12: =IF($A12="","",IF(B12=0,"-",COUNTIFS(tblTasks[Designer],$A12,tblTasks[Actual End Date],">="&$B$4,tblTasks[Actual End Date],"<="&$B$5,tblTasks[Delivery Status],"Done On Time")/B12)) -> - | E12: =IF($A12="","",IF(B12=0,"-",SUMIFS(tblTasks[Revision Rounds],tblTasks[Designer],$A12,tblTasks[Actual End Date],">="&$B$4,tblTasks[Actual End Date],"<="&$B$5)/B12)) -> - | F12: =IF($A12="","",IF(B12=0,"-",IFERROR(AVERAGEIFS(tblTasks[Speed Score],tblTasks[Designer],$A12,tblTasks[Actual End Date],">="&$B$4,tblTasks[Actual End Date],"<="&$B$5),"-"))) -> - | G12: =IF($A12="","",IF(B12=0,"-",IFERROR(AVERAGEIFS(tblTasks[Quality Score],tblTasks[Designer],$A12,tblTasks[Actual End Date],">="&$B$4,tblTasks[Actual End Date],"<="&$B$5),"-"))) -> - | H12: =IF($A12="","",IFERROR(100*(1-COUNTIFS(tblTasks[Designer],$A12,tblTasks[Delivery Status],"Overdue")/COUNTIFS(tblTasks[Designer],$A12,tblTasks[Actual End Date],"")),100)) -> 100 | I12: =IF($A12="","",IF(AND(ISNUMBER(F12),ISNUMBER(G12)),(Settings!$J$5*F12+Settings!$J$6*G12+Settings!$J$7*H12)/Settings!$J$8,"-")) -> - | J12: =IF($A12="","",IF(NOT(ISNUMBER(I12)),"-",IF(I12>=Settings!$J$10,"Excellent",IF(I12>=Settings!$J$11,"Good",IF(I12>=Settings!$J$12,"Needs Improvement","At Risk"))))) -> - | K12: =IF($A12="","",IF(NOT(ISNUMBER(I12)),"Needs at least one completed task in the period",IF(MIN(F12:H12)>=90,"Strong across all areas – keep it up",IF(F12=MIN(F12:H12),"Speed: tasks take longer than planned – raise delays early and plan realistic dates",IF(G12=MIN(F12:H12),"Quality: too many revision rounds – confirm the brief and self-review before sharing","Commitment: open tasks are past target date – update status or log the blocker"))))) -> Needs at least one completed task in the period
A13: =IF(Settings!A6="","",Settings!A6) -> Swathi | B13: =IF($A13="","",COUNTIFS(tblTasks[Designer],$A13,tblTasks[Actual End Date],">="&$B$4,tblTasks[Actual End Date],"<="&$B$5)) -> 0 | C13: =IF($A13="","",IF(B13=0,"-",IFERROR(AVERAGEIFS(tblTasks[TAT (Working Days)],tblTasks[Designer],$A13,tblTasks[Actual End Date],">="&$B$4,tblTasks[Actual End Date],"<="&$B$5),"-"))) -> - | D13: =IF($A13="","",IF(B13=0,"-",COUNTIFS(tblTasks[Designer],$A13,tblTasks[Actual End Date],">="&$B$4,tblTasks[Actual End Date],"<="&$B$5,tblTasks[Delivery Status],"Done On Time")/B13)) -> - | E13: =IF($A13="","",IF(B13=0,"-",SUMIFS(tblTasks[Revision Rounds],tblTasks[Designer],$A13,tblTasks[Actual End Date],">="&$B$4,tblTasks[Actual End Date],"<="&$B$5)/B13)) -> - | F13: =IF($A13="","",IF(B13=0,"-",IFERROR(AVERAGEIFS(tblTasks[Speed Score],tblTasks[Designer],$A13,tblTasks[Actual End Date],">="&$B$4,tblTasks[Actual End Date],"<="&$B$5),"-"))) -> - | G13: =IF($A13="","",IF(B13=0,"-",IFERROR(AVERAGEIFS(tblTasks[Quality Score],tblTasks[Designer],$A13,tblTasks[Actual End Date],">="&$B$4,tblTasks[Actual End Date],"<="&$B$5),"-"))) -> - | H13: =IF($A13="","",IFERROR(100*(1-COUNTIFS(tblTasks[Designer],$A13,tblTasks[Delivery Status],"Overdue")/COUNTIFS(tblTasks[Designer],$A13,tblTasks[Actual End Date],"")),100)) -> 100 | I13: =IF($A13="","",IF(AND(ISNUMBER(F13),ISNUMBER(G13)),(Settings!$J$5*F13+Settings!$J$6*G13+Settings!$J$7*H13)/Settings!$J$8,"-")) -> - | J13: =IF($A13="","",IF(NOT(ISNUMBER(I13)),"-",IF(I13>=Settings!$J$10,"Excellent",IF(I13>=Settings!$J$11,"Good",IF(I13>=Settings!$J$12,"Needs Improvement","At Risk"))))) -> - | K13: =IF($A13="","",IF(NOT(ISNUMBER(I13)),"Needs at least one completed task in the period",IF(MIN(F13:H13)>=90,"Strong across all areas – keep it up",IF(F13=MIN(F13:H13),"Speed: tasks take longer than planned – raise delays early and plan realistic dates",IF(G13=MIN(F13:H13),"Quality: too many revision rounds – confirm the brief and self-review before sharing","Commitment: open tasks are past target date – update status or log the blocker"))))) -> Needs at least one completed task in the period
A14: =IF(Settings!A7="","",Settings!A7) | B14: =IF($A14="","",COUNTIFS(tblTasks[Designer],$A14,tblTasks[Actual End Date],">="&$B$4,tblTasks[Actual End Date],"<="&$B$5)) | C14: =IF($A14="","",IF(B14=0,"-",IFERROR(AVERAGEIFS(tblTasks[TAT (Working Days)],tblTasks[Designer],$A14,tblTasks[Actual End Date],">="&$B$4,tblTasks[Actual End Date],"<="&$B$5),"-"))) | D14: =IF($A14="","",IF(B14=0,"-",COUNTIFS(tblTasks[Designer],$A14,tblTasks[Actual End Date],">="&$B$4,tblTasks[Actual End Date],"<="&$B$5,tblTasks[Delivery Status],"Done On Time")/B14)) | E14: =IF($A14="","",IF(B14=0,"-",SUMIFS(tblTasks[Revision Rounds],tblTasks[Designer],$A14,tblTasks[Actual End Date],">="&$B$4,tblTasks[Actual End Date],"<="&$B$5)/B14)) | F14: =IF($A14="","",IF(B14=0,"-",IFERROR(AVERAGEIFS(tblTasks[Speed Score],tblTasks[Designer],$A14,tblTasks[Actual End Date],">="&$B$4,tblTasks[Actual End Date],"<="&$B$5),"-"))) | G14: =IF($A14="","",IF(B14=0,"-",IFERROR(AVERAGEIFS(tblTasks[Quality Score],tblTasks[Designer],$A14,tblTasks[Actual End Date],">="&$B$4,tblTasks[Actual End Date],"<="&$B$5),"-"))) | H14: =IF($A14="","",IFERROR(100*(1-COUNTIFS(tblTasks[Designer],$A14,tblTasks[Delivery Status],"Overdue")/COUNTIFS(tblTasks[Designer],$A14,tblTasks[Actual End Date],"")),100)) | I14: =IF($A14="","",IF(AND(ISNUMBER(F14),ISNUMBER(G14)),(Settings!$J$5*F14+Settings!$J$6*G14+Settings!$J$7*H14)/Settings!$J$8,"-")) | J14: =IF($A14="","",IF(NOT(ISNUMBER(I14)),"-",IF(I14>=Settings!$J$10,"Excellent",IF(I14>=Settings!$J$11,"Good",IF(I14>=Settings!$J$12,"Needs Improvement","At Risk"))))) | K14: =IF($A14="","",IF(NOT(ISNUMBER(I14)),"Needs at least one completed task in the period",IF(MIN(F14:H14)>=90,"Strong across all areas – keep it up",IF(F14=MIN(F14:H14),"Speed: tasks take longer than planned – raise delays early and plan realistic dates",IF(G14=MIN(F14:H14),"Quality: too many revision rounds – confirm the brief and self-review before sharing","Commitment: open tasks are past target date – update status or log the blocker")))))
A15: =IF(Settings!A8="","",Settings!A8) | B15: =IF($A15="","",COUNTIFS(tblTasks[Designer],$A15,tblTasks[Actual End Date],">="&$B$4,tblTasks[Actual End Date],"<="&$B$5)) | C15: =IF($A15="","",IF(B15=0,"-",IFERROR(AVERAGEIFS(tblTasks[TAT (Working Days)],tblTasks[Designer],$A15,tblTasks[Actual End Date],">="&$B$4,tblTasks[Actual End Date],"<="&$B$5),"-"))) | D15: =IF($A15="","",IF(B15=0,"-",COUNTIFS(tblTasks[Designer],$A15,tblTasks[Actual End Date],">="&$B$4,tblTasks[Actual End Date],"<="&$B$5,tblTasks[Delivery Status],"Done On Time")/B15)) | E15: =IF($A15="","",IF(B15=0,"-",SUMIFS(tblTasks[Revision Rounds],tblTasks[Designer],$A15,tblTasks[Actual End Date],">="&$B$4,tblTasks[Actual End Date],"<="&$B$5)/B15)) | F15: =IF($A15="","",IF(B15=0,"-",IFERROR(AVERAGEIFS(tblTasks[Speed Score],tblTasks[Designer],$A15,tblTasks[Actual End Date],">="&$B$4,tblTasks[Actual End Date],"<="&$B$5),"-"))) | G15: =IF($A15="","",IF(B15=0,"-",IFERROR(AVERAGEIFS(tblTasks[Quality Score],tblTasks[Designer],$A15,tblTasks[Actual End Date],">="&$B$4,tblTasks[Actual End Date],"<="&$B$5),"-"))) | H15: =IF($A15="","",IFERROR(100*(1-COUNTIFS(tblTasks[Designer],$A15,tblTasks[Delivery Status],"Overdue")/COUNTIFS(tblTasks[Designer],$A15,tblTasks[Actual End Date],"")),100)) | I15: =IF($A15="","",IF(AND(ISNUMBER(F15),ISNUMBER(G15)),(Settings!$J$5*F15+Settings!$J$6*G15+Settings!$J$7*H15)/Settings!$J$8,"-")) | J15: =IF($A15="","",IF(NOT(ISNUMBER(I15)),"-",IF(I15>=Settings!$J$10,"Excellent",IF(I15>=Settings!$J$11,"Good",IF(I15>=Settings!$J$12,"Needs Improvement","At Risk"))))) | K15: =IF($A15="","",IF(NOT(ISNUMBER(I15)),"Needs at least one completed task in the period",IF(MIN(F15:H15)>=90,"Strong across all areas – keep it up",IF(F15=MIN(F15:H15),"Speed: tasks take longer than planned – raise delays early and plan realistic dates",IF(G15=MIN(F15:H15),"Quality: too many revision rounds – confirm the brief and self-review before sharing","Commitment: open tasks are past target date – update status or log the blocker")))))
A16: =IF(Settings!A9="","",Settings!A9) | B16: =IF($A16="","",COUNTIFS(tblTasks[Designer],$A16,tblTasks[Actual End Date],">="&$B$4,tblTasks[Actual End Date],"<="&$B$5)) | C16: =IF($A16="","",IF(B16=0,"-",IFERROR(AVERAGEIFS(tblTasks[TAT (Working Days)],tblTasks[Designer],$A16,tblTasks[Actual End Date],">="&$B$4,tblTasks[Actual End Date],"<="&$B$5),"-"))) | D16: =IF($A16="","",IF(B16=0,"-",COUNTIFS(tblTasks[Designer],$A16,tblTasks[Actual End Date],">="&$B$4,tblTasks[Actual End Date],"<="&$B$5,tblTasks[Delivery Status],"Done On Time")/B16)) | E16: =IF($A16="","",IF(B16=0,"-",SUMIFS(tblTasks[Revision Rounds],tblTasks[Designer],$A16,tblTasks[Actual End Date],">="&$B$4,tblTasks[Actual End Date],"<="&$B$5)/B16)) | F16: =IF($A16="","",IF(B16=0,"-",IFERROR(AVERAGEIFS(tblTasks[Speed Score],tblTasks[Designer],$A16,tblTasks[Actual End Date],">="&$B$4,tblTasks[Actual End Date],"<="&$B$5),"-"))) | G16: =IF($A16="","",IF(B16=0,"-",IFERROR(AVERAGEIFS(tblTasks[Quality Score],tblTasks[Designer],$A16,tblTasks[Actual End Date],">="&$B$4,tblTasks[Actual End Date],"<="&$B$5),"-"))) | H16: =IF($A16="","",IFERROR(100*(1-COUNTIFS(tblTasks[Designer],$A16,tblTasks[Delivery Status],"Overdue")/COUNTIFS(tblTasks[Designer],$A16,tblTasks[Actual End Date],"")),100)) | I16: =IF($A16="","",IF(AND(ISNUMBER(F16),ISNUMBER(G16)),(Settings!$J$5*F16+Settings!$J$6*G16+Settings!$J$7*H16)/Settings!$J$8,"-")) | J16: =IF($A16="","",IF(NOT(ISNUMBER(I16)),"-",IF(I16>=Settings!$J$10,"Excellent",IF(I16>=Settings!$J$11,"Good",IF(I16>=Settings!$J$12,"Needs Improvement","At Risk"))))) | K16: =IF($A16="","",IF(NOT(ISNUMBER(I16)),"Needs at least one completed task in the period",IF(MIN(F16:H16)>=90,"Strong across all areas – keep it up",IF(F16=MIN(F16:H16),"Speed: tasks take longer than planned – raise delays early and plan realistic dates",IF(G16=MIN(F16:H16),"Quality: too many revision rounds – confirm the brief and self-review before sharing","Commitment: open tasks are past target date – update status or log the blocker")))))
A18: Tasks by PM
A19: PM | B19: Tasks Created | C19: Open | D19: Blocked | E19: Overdue | F19: Avg Revision Rounds (completed)
A20: =IF(Settings!B5="","",Settings!B5) -> Raghav | B20: =IF($A20="","",COUNTIFS(tblTasks[PM (Project Lead)],$A20)) -> 0 | C20: =IF($A20="","",COUNTIFS(tblTasks[PM (Project Lead)],$A20,tblTasks[Actual End Date],"")) -> 0 | D20: =IF($A20="","",COUNTIFS(tblTasks[PM (Project Lead)],$A20,tblTasks[Delivery Status],"Blocked")) -> 0 | E20: =IF($A20="","",COUNTIFS(tblTasks[PM (Project Lead)],$A20,tblTasks[Delivery Status],"Overdue")) -> 0 | F20: =IF($A20="","",IFERROR(SUMIFS(tblTasks[Revision Rounds],tblTasks[PM (Project Lead)],$A20,tblTasks[Delivery Status],"Done*")/COUNTIFS(tblTasks[PM (Project Lead)],$A20,tblTasks[Delivery Status],"Done*"),"-")) -> -
A21: =IF(Settings!B6="","",Settings!B6) -> SL | B21: =IF($A21="","",COUNTIFS(tblTasks[PM (Project Lead)],$A21)) -> 0 | C21: =IF($A21="","",COUNTIFS(tblTasks[PM (Project Lead)],$A21,tblTasks[Actual End Date],"")) -> 0 | D21: =IF($A21="","",COUNTIFS(tblTasks[PM (Project Lead)],$A21,tblTasks[Delivery Status],"Blocked")) -> 0 | E21: =IF($A21="","",COUNTIFS(tblTasks[PM (Project Lead)],$A21,tblTasks[Delivery Status],"Overdue")) -> 0 | F21: =IF($A21="","",IFERROR(SUMIFS(tblTasks[Revision Rounds],tblTasks[PM (Project Lead)],$A21,tblTasks[Delivery Status],"Done*")/COUNTIFS(tblTasks[PM (Project Lead)],$A21,tblTasks[Delivery Status],"Done*"),"-")) -> -
A22: =IF(Settings!B7="","",Settings!B7) -> Arun | B22: =IF($A22="","",COUNTIFS(tblTasks[PM (Project Lead)],$A22)) -> 0 | C22: =IF($A22="","",COUNTIFS(tblTasks[PM (Project Lead)],$A22,tblTasks[Actual End Date],"")) -> 0 | D22: =IF($A22="","",COUNTIFS(tblTasks[PM (Project Lead)],$A22,tblTasks[Delivery Status],"Blocked")) -> 0 | E22: =IF($A22="","",COUNTIFS(tblTasks[PM (Project Lead)],$A22,tblTasks[Delivery Status],"Overdue")) -> 0 | F22: =IF($A22="","",IFERROR(SUMIFS(tblTasks[Revision Rounds],tblTasks[PM (Project Lead)],$A22,tblTasks[Delivery Status],"Done*")/COUNTIFS(tblTasks[PM (Project Lead)],$A22,tblTasks[Delivery Status],"Done*"),"-")) -> -
A23: =IF(Settings!B8="","",Settings!B8) -> Naveen | B23: =IF($A23="","",COUNTIFS(tblTasks[PM (Project Lead)],$A23)) -> 0 | C23: =IF($A23="","",COUNTIFS(tblTasks[PM (Project Lead)],$A23,tblTasks[Actual End Date],"")) -> 0 | D23: =IF($A23="","",COUNTIFS(tblTasks[PM (Project Lead)],$A23,tblTasks[Delivery Status],"Blocked")) -> 0 | E23: =IF($A23="","",COUNTIFS(tblTasks[PM (Project Lead)],$A23,tblTasks[Delivery Status],"Overdue")) -> 0 | F23: =IF($A23="","",IFERROR(SUMIFS(tblTasks[Revision Rounds],tblTasks[PM (Project Lead)],$A23,tblTasks[Delivery Status],"Done*")/COUNTIFS(tblTasks[PM (Project Lead)],$A23,tblTasks[Delivery Status],"Done*"),"-")) -> -
A24: =IF(Settings!B9="","",Settings!B9) -> Manu | B24: =IF($A24="","",COUNTIFS(tblTasks[PM (Project Lead)],$A24)) -> 0 | C24: =IF($A24="","",COUNTIFS(tblTasks[PM (Project Lead)],$A24,tblTasks[Actual End Date],"")) -> 0 | D24: =IF($A24="","",COUNTIFS(tblTasks[PM (Project Lead)],$A24,tblTasks[Delivery Status],"Blocked")) -> 0 | E24: =IF($A24="","",COUNTIFS(tblTasks[PM (Project Lead)],$A24,tblTasks[Delivery Status],"Overdue")) -> 0 | F24: =IF($A24="","",IFERROR(SUMIFS(tblTasks[Revision Rounds],tblTasks[PM (Project Lead)],$A24,tblTasks[Delivery Status],"Done*")/COUNTIFS(tblTasks[PM (Project Lead)],$A24,tblTasks[Delivery Status],"Done*"),"-")) -> -
A26: How the score works
A27: ="Speed ("&TEXT(Settings!J5,"0%")&"): planned working days ÷ actual working days per task, capped at 100. Finishing on or before the target date scores 100." -> Speed (40%): planned working days ÷ actual working days per task, capped at 100. Finishing on or before the target date scores 100.
A28: ="Quality ("&TEXT(Settings!J6,"0%")&"): starts at 100 and drops with each revision round; reaches 0 at "&Settings!J9&" rounds." -> Quality (40%): starts at 100 and drops with each revision round; reaches 0 at 4 rounds.
A29: ="Commitment ("&TEXT(Settings!J7,"0%")&"): share of open tasks that are not past their target date. Blocked tasks (with a blocker logged) are not counted as overdue." -> Commitment (20%): share of open tasks that are not past their target date. Blocked tasks (with a blocker logged) are not counted as overdue.
A30: ="Overall = weighted average. Ratings: Excellent ≥ "&Settings!J10&", Good ≥ "&Settings!J11&", Needs Improvement ≥ "&Settings!J12&", otherwise At Risk." -> Overall = weighted average. Ratings: Excellent ≥ 85, Good ≥ 70, Needs Improvement ≥ 50, otherwise At Risk.
A31: Weights, thresholds and names can be changed on the Settings tab.
A33: Weekly workload
A34: Show weeks from (any date) | B34: =TODAY() -> 46294 | C34: ="Capacity "&Settings!J16&" hrs/week ("&Settings!J17&"-day week = "&TEXT(Settings!J18,"0.0")&" hrs/day). Hours are spread evenly over each task's working days between Start and Target End." -> Capacity 48 hrs/week (5-day week = 9.6 hrs/day). Hours are spread evenly over each task's working days between Start and Target End.
A35: ="Open tasks with no effort estimate (not counted in workload): "&COUNTIFS(tblTasks[Task Assigned],"<>",tblTasks[Estimated Effort (Hrs)],"",tblTasks[Actual End Date],"") -> Open tasks with no effort estimate (not counted in workload): 0
A36: Designer | B36: Week starting (Mon) | C36: =$B$34-WEEKDAY($B$34,2)+1 -> 46293 | D36: =C36+7 -> 46300 | E36: =D36+7 -> 46307 | F36: =E36+7 -> 46314 | G36: =F36+7 -> 46321 | H36: =G36+7 -> 46328 | I36: =H36+7 -> 46335 | J36: =I36+7 -> 46342
B37: Holidays (working days) | C37: {=SUMPRODUCT((COUNTIF(tblHolidays[Holiday Date],C$36+{0,1,2,3,4,5})>0)*(WEEKDAY(C$36+{0,1,2,3,4,5},2)<=Settings!$J$17))} -> 0 | D37: {=SUMPRODUCT((COUNTIF(tblHolidays[Holiday Date],D$36+{0,1,2,3,4,5})>0)*(WEEKDAY(D$36+{0,1,2,3,4,5},2)<=Settings!$J$17))} -> 0 | E37: {=SUMPRODUCT((COUNTIF(tblHolidays[Holiday Date],E$36+{0,1,2,3,4,5})>0)*(WEEKDAY(E$36+{0,1,2,3,4,5},2)<=Settings!$J$17))} -> 0 | F37: {=SUMPRODUCT((COUNTIF(tblHolidays[Holiday Date],F$36+{0,1,2,3,4,5})>0)*(WEEKDAY(F$36+{0,1,2,3,4,5},2)<=Settings!$J$17))} -> 0 | G37: {=SUMPRODUCT((COUNTIF(tblHolidays[Holiday Date],G$36+{0,1,2,3,4,5})>0)*(WEEKDAY(G$36+{0,1,2,3,4,5},2)<=Settings!$J$17))} -> 0 | H37: {=SUMPRODUCT((COUNTIF(tblHolidays[Holiday Date],H$36+{0,1,2,3,4,5})>0)*(WEEKDAY(H$36+{0,1,2,3,4,5},2)<=Settings!$J$17))} -> 0 | I37: {=SUMPRODUCT((COUNTIF(tblHolidays[Holiday Date],I$36+{0,1,2,3,4,5})>0)*(WEEKDAY(I$36+{0,1,2,3,4,5},2)<=Settings!$J$17))} -> 0 | J37: {=SUMPRODUCT((COUNTIF(tblHolidays[Holiday Date],J$36+{0,1,2,3,4,5})>0)*(WEEKDAY(J$36+{0,1,2,3,4,5},2)<=Settings!$J$17))} -> 0
A38: =IF(Settings!A5="","",Settings!A5) -> Pragati | B38: Leave (days) | C38: {=IF($A$38="","",SUMPRODUCT((COUNTIFS(tblLeave[Designer],$A$38,tblLeave[From],"<="&(C$36+{0,1,2,3,4,5}),tblLeave[To],">="&(C$36+{0,1,2,3,4,5}))>0)*(COUNTIF(tblHolidays[Holiday Date],C$36+{0,1,2,3,4,5})=0)*(WEEKDAY(C$36+{0,1,2,3,4,5},2)<=Settings!$J$17)))} -> 0 | D38: {=IF($A$38="","",SUMPRODUCT((COUNTIFS(tblLeave[Designer],$A$38,tblLeave[From],"<="&(D$36+{0,1,2,3,4,5}),tblLeave[To],">="&(D$36+{0,1,2,3,4,5}))>0)*(COUNTIF(tblHolidays[Holiday Date],D$36+{0,1,2,3,4,5})=0)*(WEEKDAY(D$36+{0,1,2,3,4,5},2)<=Settings!$J$17)))} -> 0 | E38: {=IF($A$38="","",SUMPRODUCT((COUNTIFS(tblLeave[Designer],$A$38,tblLeave[From],"<="&(E$36+{0,1,2,3,4,5}),tblLeave[To],">="&(E$36+{0,1,2,3,4,5}))>0)*(COUNTIF(tblHolidays[Holiday Date],E$36+{0,1,2,3,4,5})=0)*(WEEKDAY(E$36+{0,1,2,3,4,5},2)<=Settings!$J$17)))} -> 0 | F38: {=IF($A$38="","",SUMPRODUCT((COUNTIFS(tblLeave[Designer],$A$38,tblLeave[From],"<="&(F$36+{0,1,2,3,4,5}),tblLeave[To],">="&(F$36+{0,1,2,3,4,5}))>0)*(COUNTIF(tblHolidays[Holiday Date],F$36+{0,1,2,3,4,5})=0)*(WEEKDAY(F$36+{0,1,2,3,4,5},2)<=Settings!$J$17)))} -> 0 | G38: {=IF($A$38="","",SUMPRODUCT((COUNTIFS(tblLeave[Designer],$A$38,tblLeave[From],"<="&(G$36+{0,1,2,3,4,5}),tblLeave[To],">="&(G$36+{0,1,2,3,4,5}))>0)*(COUNTIF(tblHolidays[Holiday Date],G$36+{0,1,2,3,4,5})=0)*(WEEKDAY(G$36+{0,1,2,3,4,5},2)<=Settings!$J$17)))} -> 0 | H38: {=IF($A$38="","",SUMPRODUCT((COUNTIFS(tblLeave[Designer],$A$38,tblLeave[From],"<="&(H$36+{0,1,2,3,4,5}),tblLeave[To],">="&(H$36+{0,1,2,3,4,5}))>0)*(COUNTIF(tblHolidays[Holiday Date],H$36+{0,1,2,3,4,5})=0)*(WEEKDAY(H$36+{0,1,2,3,4,5},2)<=Settings!$J$17)))} -> 0 | I38: {=IF($A$38="","",SUMPRODUCT((COUNTIFS(tblLeave[Designer],$A$38,tblLeave[From],"<="&(I$36+{0,1,2,3,4,5}),tblLeave[To],">="&(I$36+{0,1,2,3,4,5}))>0)*(COUNTIF(tblHolidays[Holiday Date],I$36+{0,1,2,3,4,5})=0)*(WEEKDAY(I$36+{0,1,2,3,4,5},2)<=Settings!$J$17)))} -> 0 | J38: {=IF($A$38="","",SUMPRODUCT((COUNTIFS(tblLeave[Designer],$A$38,tblLeave[From],"<="&(J$36+{0,1,2,3,4,5}),tblLeave[To],">="&(J$36+{0,1,2,3,4,5}))>0)*(COUNTIF(tblHolidays[Holiday Date],J$36+{0,1,2,3,4,5})=0)*(WEEKDAY(J$36+{0,1,2,3,4,5},2)<=Settings!$J$17)))} -> 0
B39: Available (hrs) | C39: =IF($A$38="","",MAX(0,Settings!$J$17-C$37-C38)*Settings!$J$18) -> 48 | D39: =IF($A$38="","",MAX(0,Settings!$J$17-D$37-D38)*Settings!$J$18) -> 48 | E39: =IF($A$38="","",MAX(0,Settings!$J$17-E$37-E38)*Settings!$J$18) -> 48 | F39: =IF($A$38="","",MAX(0,Settings!$J$17-F$37-F38)*Settings!$J$18) -> 48 | G39: =IF($A$38="","",MAX(0,Settings!$J$17-G$37-G38)*Settings!$J$18) -> 48 | H39: =IF($A$38="","",MAX(0,Settings!$J$17-H$37-H38)*Settings!$J$18) -> 48 | I39: =IF($A$38="","",MAX(0,Settings!$J$17-I$37-I38)*Settings!$J$18) -> 48 | J39: =IF($A$38="","",MAX(0,Settings!$J$17-J$37-J38)*Settings!$J$18) -> 48
B40: Allocated (hrs) | C40: {=IF($A$38="","",SUMPRODUCT(SUMIFS(tblTasks[Hours per Working Day],tblTasks[Designer],$A$38,tblTasks[Start Date],"<="&(C$36+{0,1,2,3,4,5}),tblTasks[Target End Date],">="&(C$36+{0,1,2,3,4,5}))*(COUNTIF(tblHolidays[Holiday Date],C$36+{0,1,2,3,4,5})=0)*(WEEKDAY(C$36+{0,1,2,3,4,5},2)<=Settings!$J$17)))} -> 0 | D40: {=IF($A$38="","",SUMPRODUCT(SUMIFS(tblTasks[Hours per Working Day],tblTasks[Designer],$A$38,tblTasks[Start Date],"<="&(D$36+{0,1,2,3,4,5}),tblTasks[Target End Date],">="&(D$36+{0,1,2,3,4,5}))*(COUNTIF(tblHolidays[Holiday Date],D$36+{0,1,2,3,4,5})=0)*(WEEKDAY(D$36+{0,1,2,3,4,5},2)<=Settings!$J$17)))} -> 0 | E40: {=IF($A$38="","",SUMPRODUCT(SUMIFS(tblTasks[Hours per Working Day],tblTasks[Designer],$A$38,tblTasks[Start Date],"<="&(E$36+{0,1,2,3,4,5}),tblTasks[Target End Date],">="&(E$36+{0,1,2,3,4,5}))*(COUNTIF(tblHolidays[Holiday Date],E$36+{0,1,2,3,4,5})=0)*(WEEKDAY(E$36+{0,1,2,3,4,5},2)<=Settings!$J$17)))} -> 0 | F40: {=IF($A$38="","",SUMPRODUCT(SUMIFS(tblTasks[Hours per Working Day],tblTasks[Designer],$A$38,tblTasks[Start Date],"<="&(F$36+{0,1,2,3,4,5}),tblTasks[Target End Date],">="&(F$36+{0,1,2,3,4,5}))*(COUNTIF(tblHolidays[Holiday Date],F$36+{0,1,2,3,4,5})=0)*(WEEKDAY(F$36+{0,1,2,3,4,5},2)<=Settings!$J$17)))} -> 0 | G40: {=IF($A$38="","",SUMPRODUCT(SUMIFS(tblTasks[Hours per Working Day],tblTasks[Designer],$A$38,tblTasks[Start Date],"<="&(G$36+{0,1,2,3,4,5}),tblTasks[Target End Date],">="&(G$36+{0,1,2,3,4,5}))*(COUNTIF(tblHolidays[Holiday Date],G$36+{0,1,2,3,4,5})=0)*(WEEKDAY(G$36+{0,1,2,3,4,5},2)<=Settings!$J$17)))} -> 0 | H40: {=IF($A$38="","",SUMPRODUCT(SUMIFS(tblTasks[Hours per Working Day],tblTasks[Designer],$A$38,tblTasks[Start Date],"<="&(H$36+{0,1,2,3,4,5}),tblTasks[Target End Date],">="&(H$36+{0,1,2,3,4,5}))*(COUNTIF(tblHolidays[Holiday Date],H$36+{0,1,2,3,4,5})=0)*(WEEKDAY(H$36+{0,1,2,3,4,5},2)<=Settings!$J$17)))} -> 0 | I40: {=IF($A$38="","",SUMPRODUCT(SUMIFS(tblTasks[Hours per Working Day],tblTasks[Designer],$A$38,tblTasks[Start Date],"<="&(I$36+{0,1,2,3,4,5}),tblTasks[Target End Date],">="&(I$36+{0,1,2,3,4,5}))*(COUNTIF(tblHolidays[Holiday Date],I$36+{0,1,2,3,4,5})=0)*(WEEKDAY(I$36+{0,1,2,3,4,5},2)<=Settings!$J$17)))} -> 0 | J40: {=IF($A$38="","",SUMPRODUCT(SUMIFS(tblTasks[Hours per Working Day],tblTasks[Designer],$A$38,tblTasks[Start Date],"<="&(J$36+{0,1,2,3,4,5}),tblTasks[Target End Date],">="&(J$36+{0,1,2,3,4,5}))*(COUNTIF(tblHolidays[Holiday Date],J$36+{0,1,2,3,4,5})=0)*(WEEKDAY(J$36+{0,1,2,3,4,5},2)<=Settings!$J$17)))} -> 0
B41: Utilisation | C41: =IF($A$38="","",IF(C39=0,IF(C40>0,"No capacity","-"),C40/C39)) -> 0 | D41: =IF($A$38="","",IF(D39=0,IF(D40>0,"No capacity","-"),D40/D39)) -> 0 | E41: =IF($A$38="","",IF(E39=0,IF(E40>0,"No capacity","-"),E40/E39)) -> 0 | F41: =IF($A$38="","",IF(F39=0,IF(F40>0,"No capacity","-"),F40/F39)) -> 0 | G41: =IF($A$38="","",IF(G39=0,IF(G40>0,"No capacity","-"),G40/G39)) -> 0 | H41: =IF($A$38="","",IF(H39=0,IF(H40>0,"No capacity","-"),H40/H39)) -> 0 | I41: =IF($A$38="","",IF(I39=0,IF(I40>0,"No capacity","-"),I40/I39)) -> 0 | J41: =IF($A$38="","",IF(J39=0,IF(J40>0,"No capacity","-"),J40/J39)) -> 0
B42: Headroom (hrs) | C42: =IF($A$38="","",C39-C40) -> 48 | D42: =IF($A$38="","",D39-D40) -> 48 | E42: =IF($A$38="","",E39-E40) -> 48 | F42: =IF($A$38="","",F39-F40) -> 48 | G42: =IF($A$38="","",G39-G40) -> 48 | H42: =IF($A$38="","",H39-H40) -> 48 | I42: =IF($A$38="","",I39-I40) -> 48 | J42: =IF($A$38="","",J39-J40) -> 48
